[2024-02-12T19:26:16.865+0000] {taskinstance.py:1083} INFO - Dependencies all met for <TaskInstance: windturbine.get_data scheduled__2024-02-12T19:21:00+00:00 [queued]>
[2024-02-12T19:26:16.917+0000] {taskinstance.py:1083} INFO - Dependencies all met for <TaskInstance: windturbine.get_data scheduled__2024-02-12T19:21:00+00:00 [queued]>
[2024-02-12T19:26:16.918+0000] {taskinstance.py:1279} INFO - 
--------------------------------------------------------------------------------
[2024-02-12T19:26:16.918+0000] {taskinstance.py:1280} INFO - Starting attempt 1 of 2
[2024-02-12T19:26:16.919+0000] {taskinstance.py:1281} INFO - 
--------------------------------------------------------------------------------
[2024-02-12T19:26:16.963+0000] {taskinstance.py:1300} INFO - Executing <Task(PythonOperator): get_data> on 2024-02-12 19:21:00+00:00
[2024-02-12T19:26:16.978+0000] {standard_task_runner.py:55} INFO - Started process 2071 to run task
[2024-02-12T19:26:16.989+0000] {standard_task_runner.py:82} INFO - Running: ['***', 'tasks', 'run', 'windturbine', 'get_data', 'scheduled__2024-02-12T19:21:00+00:00', '--job-id', '1117', '--raw', '--subdir', 'DAGS_FOLDER/windturbine.py', '--cfg-path', '/tmp/tmpimli82ax']
[2024-02-12T19:26:16.992+0000] {standard_task_runner.py:83} INFO - Job 1117: Subtask get_data
[2024-02-12T19:26:17.338+0000] {task_command.py:388} INFO - Running <TaskInstance: windturbine.get_data scheduled__2024-02-12T19:21:00+00:00 [running]> on host b5b8d61630c3
[2024-02-12T19:26:17.883+0000] {taskinstance.py:1509} INFO - Exporting the following env vars:
AIRFLOW_CTX_DAG_EMAIL=guilherme.ribeiro.business@gmail.com
AIRFLOW_CTX_DAG_OWNER=***
AIRFLOW_CTX_DAG_ID=windturbine
AIRFLOW_CTX_TASK_ID=get_data
AIRFLOW_CTX_EXECUTION_DATE=2024-02-12T19:21:00+00:00
AIRFLOW_CTX_TRY_NUMBER=1
AIRFLOW_CTX_DAG_RUN_ID=scheduled__2024-02-12T19:21:00+00:00
[2024-02-12T19:26:17.905+0000] {taskinstance.py:1768} ERROR - Task failed with exception
Traceback (most recent call last):
  File "/home/airflow/.local/lib/python3.7/site-packages/airflow/operators/python.py", line 175, in execute
    return_value = self.execute_callable()
  File "/home/airflow/.local/lib/python3.7/site-packages/airflow/operators/python.py", line 192, in execute_callable
    return self.python_callable(*self.op_args, **self.op_kwargs)
  File "/opt/airflow/dags/windturbine.py", line 40, in process_file
    with open(Variable.get('path_file')) as f:
FileNotFoundError: [Errno 2] No such file or directory: '/opt/airflow/data/data.json'
[2024-02-12T19:26:17.955+0000] {taskinstance.py:1323} INFO - Marking task as UP_FOR_RETRY. dag_id=windturbine, task_id=get_data, execution_date=20240212T192100, start_date=20240212T192616, end_date=20240212T192617
[2024-02-12T19:26:18.004+0000] {standard_task_runner.py:105} ERROR - Failed to execute job 1117 for task get_data ([Errno 2] No such file or directory: '/opt/airflow/data/data.json'; 2071)
[2024-02-12T19:26:18.127+0000] {local_task_job.py:208} INFO - Task exited with return code 1
[2024-02-12T19:26:18.410+0000] {taskinstance.py:2578} INFO - 0 downstream tasks scheduled from follow-on schedule check
