[2024-02-02T10:55:25.268+0000] {taskinstance.py:1083} INFO - Dependencies all met for <TaskInstance: variaveis.tsk1 manual__2024-02-02T10:55:22.909452+00:00 [queued]>
[2024-02-02T10:55:25.286+0000] {taskinstance.py:1083} INFO - Dependencies all met for <TaskInstance: variaveis.tsk1 manual__2024-02-02T10:55:22.909452+00:00 [queued]>
[2024-02-02T10:55:25.287+0000] {taskinstance.py:1279} INFO - 
--------------------------------------------------------------------------------
[2024-02-02T10:55:25.287+0000] {taskinstance.py:1280} INFO - Starting attempt 1 of 1
[2024-02-02T10:55:25.287+0000] {taskinstance.py:1281} INFO - 
--------------------------------------------------------------------------------
[2024-02-02T10:55:25.315+0000] {taskinstance.py:1300} INFO - Executing <Task(PythonOperator): tsk1> on 2024-02-02 10:55:22.909452+00:00
[2024-02-02T10:55:25.322+0000] {standard_task_runner.py:55} INFO - Started process 1320 to run task
[2024-02-02T10:55:25.331+0000] {standard_task_runner.py:82} INFO - Running: ['***', 'tasks', 'run', 'variaveis', 'tsk1', 'manual__2024-02-02T10:55:22.909452+00:00', '--job-id', '528', '--raw', '--subdir', 'DAGS_FOLDER/variaveis.py', '--cfg-path', '/tmp/tmpid46b01h']
[2024-02-02T10:55:25.332+0000] {standard_task_runner.py:83} INFO - Job 528: Subtask tsk1
[2024-02-02T10:55:25.429+0000] {task_command.py:388} INFO - Running <TaskInstance: variaveis.tsk1 manual__2024-02-02T10:55:22.909452+00:00 [running]> on host 5b3777e64f6c
[2024-02-02T10:55:25.577+0000] {taskinstance.py:1509} INFO - Exporting the following env vars:
AIRFLOW_CTX_DAG_OWNER=***
AIRFLOW_CTX_DAG_ID=variaveis
AIRFLOW_CTX_TASK_ID=tsk1
AIRFLOW_CTX_EXECUTION_DATE=2024-02-02T10:55:22.909452+00:00
AIRFLOW_CTX_TRY_NUMBER=1
AIRFLOW_CTX_DAG_RUN_ID=manual__2024-02-02T10:55:22.909452+00:00
[2024-02-02T10:55:25.592+0000] {taskinstance.py:1768} ERROR - Task failed with exception
Traceback (most recent call last):
  File "/home/airflow/.local/lib/python3.7/site-packages/airflow/operators/python.py", line 175, in execute
    return_value = self.execute_callable()
  File "/home/airflow/.local/lib/python3.7/site-packages/airflow/operators/python.py", line 192, in execute_callable
    return self.python_callable(*self.op_args, **self.op_kwargs)
  File "/opt/airflow/dags/variaveis.py", line 14, in print_varible
    minha_var = Variable.get('minhavar')
  File "/home/airflow/.local/lib/python3.7/site-packages/airflow/models/variable.py", line 141, in get
    raise KeyError(f"Variable {key} does not exist")
KeyError: 'Variable minhavar does not exist'
[2024-02-02T10:55:25.612+0000] {taskinstance.py:1323} INFO - Marking task as FAILED. dag_id=variaveis, task_id=tsk1, execution_date=20240202T105522, start_date=20240202T105525, end_date=20240202T105525
[2024-02-02T10:55:25.646+0000] {standard_task_runner.py:105} ERROR - Failed to execute job 528 for task tsk1 ('Variable minhavar does not exist'; 1320)
[2024-02-02T10:55:25.703+0000] {local_task_job.py:208} INFO - Task exited with return code 1
[2024-02-02T10:55:25.748+0000] {taskinstance.py:2578} INFO - 0 downstream tasks scheduled from follow-on schedule check
