[2024-02-12T19:26:15.783+0000] {taskinstance.py:1083} INFO - Dependencies all met for <TaskInstance: windturbine.get_data manual__2024-02-12T19:19:18.739489+00:00 [queued]>
[2024-02-12T19:26:15.829+0000] {taskinstance.py:1083} INFO - Dependencies all met for <TaskInstance: windturbine.get_data manual__2024-02-12T19:19:18.739489+00:00 [queued]>
[2024-02-12T19:26:15.829+0000] {taskinstance.py:1279} INFO - 
--------------------------------------------------------------------------------
[2024-02-12T19:26:15.829+0000] {taskinstance.py:1280} INFO - Starting attempt 1 of 2
[2024-02-12T19:26:15.830+0000] {taskinstance.py:1281} INFO - 
--------------------------------------------------------------------------------
[2024-02-12T19:26:15.901+0000] {taskinstance.py:1300} INFO - Executing <Task(PythonOperator): get_data> on 2024-02-12 19:19:18.739489+00:00
[2024-02-12T19:26:15.914+0000] {standard_task_runner.py:55} INFO - Started process 2069 to run task
[2024-02-12T19:26:15.930+0000] {standard_task_runner.py:82} INFO - Running: ['***', 'tasks', 'run', 'windturbine', 'get_data', 'manual__2024-02-12T19:19:18.739489+00:00', '--job-id', '1115', '--raw', '--subdir', 'DAGS_FOLDER/windturbine.py', '--cfg-path', '/tmp/tmpco9ndihb']
[2024-02-12T19:26:15.941+0000] {standard_task_runner.py:83} INFO - Job 1115: Subtask get_data
[2024-02-12T19:26:16.270+0000] {task_command.py:388} INFO - Running <TaskInstance: windturbine.get_data manual__2024-02-12T19:19:18.739489+00:00 [running]> on host b5b8d61630c3
[2024-02-12T19:26:16.641+0000] {taskinstance.py:1509} INFO - Exporting the following env vars:
AIRFLOW_CTX_DAG_EMAIL=guilherme.ribeiro.business@gmail.com
AIRFLOW_CTX_DAG_OWNER=***
AIRFLOW_CTX_DAG_ID=windturbine
AIRFLOW_CTX_TASK_ID=get_data
AIRFLOW_CTX_EXECUTION_DATE=2024-02-12T19:19:18.739489+00:00
AIRFLOW_CTX_TRY_NUMBER=1
AIRFLOW_CTX_DAG_RUN_ID=manual__2024-02-12T19:19:18.739489+00:00
[2024-02-12T19:26:16.827+0000] {taskinstance.py:1768} ERROR - Task failed with exception
Traceback (most recent call last):
  File "/home/airflow/.local/lib/python3.7/site-packages/airflow/operators/python.py", line 175, in execute
    return_value = self.execute_callable()
  File "/home/airflow/.local/lib/python3.7/site-packages/airflow/operators/python.py", line 192, in execute_callable
    return self.python_callable(*self.op_args, **self.op_kwargs)
  File "/opt/airflow/dags/windturbine.py", line 47, in process_file
    os.remove(Variable.get('path_file'))
FileNotFoundError: [Errno 2] No such file or directory: '/opt/airflow/data/data.json'
[2024-02-12T19:26:16.855+0000] {taskinstance.py:1323} INFO - Marking task as UP_FOR_RETRY. dag_id=windturbine, task_id=get_data, execution_date=20240212T191918, start_date=20240212T192615, end_date=20240212T192616
[2024-02-12T19:26:16.876+0000] {standard_task_runner.py:105} ERROR - Failed to execute job 1115 for task get_data ([Errno 2] No such file or directory: '/opt/airflow/data/data.json'; 2069)
[2024-02-12T19:26:16.891+0000] {local_task_job.py:208} INFO - Task exited with return code 1
[2024-02-12T19:26:16.963+0000] {taskinstance.py:2578} INFO - 0 downstream tasks scheduled from follow-on schedule check
