[2024-02-12T14:48:56.713+0000] {taskinstance.py:1083} INFO - Dependencies all met for <TaskInstance: bigdata.big_data manual__2024-02-12T14:48:52.163096+00:00 [queued]>
[2024-02-12T14:48:56.737+0000] {taskinstance.py:1083} INFO - Dependencies all met for <TaskInstance: bigdata.big_data manual__2024-02-12T14:48:52.163096+00:00 [queued]>
[2024-02-12T14:48:56.738+0000] {taskinstance.py:1279} INFO - 
--------------------------------------------------------------------------------
[2024-02-12T14:48:56.738+0000] {taskinstance.py:1280} INFO - Starting attempt 1 of 1
[2024-02-12T14:48:56.738+0000] {taskinstance.py:1281} INFO - 
--------------------------------------------------------------------------------
[2024-02-12T14:48:56.757+0000] {taskinstance.py:1300} INFO - Executing <Task(BigDataOperator): big_data> on 2024-02-12 14:48:52.163096+00:00
[2024-02-12T14:48:56.765+0000] {standard_task_runner.py:55} INFO - Started process 133 to run task
[2024-02-12T14:48:56.770+0000] {standard_task_runner.py:82} INFO - Running: ['***', 'tasks', 'run', 'bigdata', 'big_data', 'manual__2024-02-12T14:48:52.163096+00:00', '--job-id', '1072', '--raw', '--subdir', 'DAGS_FOLDER/bigdata.py', '--cfg-path', '/tmp/tmpw4r2b55c']
[2024-02-12T14:48:56.772+0000] {standard_task_runner.py:83} INFO - Job 1072: Subtask big_data
[2024-02-12T14:48:56.852+0000] {task_command.py:388} INFO - Running <TaskInstance: bigdata.big_data manual__2024-02-12T14:48:52.163096+00:00 [running]> on host b5b8d61630c3
[2024-02-12T14:48:56.947+0000] {taskinstance.py:1509} INFO - Exporting the following env vars:
AIRFLOW_CTX_DAG_OWNER=***
AIRFLOW_CTX_DAG_ID=bigdata
AIRFLOW_CTX_TASK_ID=big_data
AIRFLOW_CTX_EXECUTION_DATE=2024-02-12T14:48:52.163096+00:00
AIRFLOW_CTX_TRY_NUMBER=1
AIRFLOW_CTX_DAG_RUN_ID=manual__2024-02-12T14:48:52.163096+00:00
[2024-02-12T14:48:56.948+0000] {taskinstance.py:1768} ERROR - Task failed with exception
Traceback (most recent call last):
  File "/home/airflow/.local/lib/python3.7/site-packages/airflow/models/baseoperator.py", line 1113, in execute
    raise NotImplementedError()
NotImplementedError
[2024-02-12T14:48:56.959+0000] {taskinstance.py:1323} INFO - Marking task as FAILED. dag_id=bigdata, task_id=big_data, execution_date=20240212T144852, start_date=20240212T144856, end_date=20240212T144856
[2024-02-12T14:48:56.974+0000] {standard_task_runner.py:105} ERROR - Failed to execute job 1072 for task big_data (; 133)
[2024-02-12T14:48:57.023+0000] {local_task_job.py:208} INFO - Task exited with return code 1
[2024-02-12T14:48:57.045+0000] {taskinstance.py:2578} INFO - 0 downstream tasks scheduled from follow-on schedule check
