[2024-02-12T12:02:18.231+0000] {taskinstance.py:1083} INFO - Dependencies all met for <TaskInstance: bigdata.big_data manual__2024-02-12T12:02:01.558922+00:00 [queued]>
[2024-02-12T12:02:18.329+0000] {taskinstance.py:1083} INFO - Dependencies all met for <TaskInstance: bigdata.big_data manual__2024-02-12T12:02:01.558922+00:00 [queued]>
[2024-02-12T12:02:18.329+0000] {taskinstance.py:1279} INFO - 
--------------------------------------------------------------------------------
[2024-02-12T12:02:18.329+0000] {taskinstance.py:1280} INFO - Starting attempt 1 of 1
[2024-02-12T12:02:18.329+0000] {taskinstance.py:1281} INFO - 
--------------------------------------------------------------------------------
[2024-02-12T12:02:18.423+0000] {taskinstance.py:1300} INFO - Executing <Task(BigDataOperator): big_data> on 2024-02-12 12:02:01.558922+00:00
[2024-02-12T12:02:18.438+0000] {standard_task_runner.py:55} INFO - Started process 1960 to run task
[2024-02-12T12:02:18.447+0000] {taskinstance.py:1077} INFO - Dependencies not met for <TaskInstance: bigdata.big_data manual__2024-02-12T12:02:01.558922+00:00 [running]>, dependency 'Task Instance State' FAILED: Task is in the 'running' state.
[2024-02-12T12:02:18.460+0000] {taskinstance.py:1077} INFO - Dependencies not met for <TaskInstance: bigdata.big_data manual__2024-02-12T12:02:01.558922+00:00 [running]>, dependency 'Task Instance Not Running' FAILED: Task is in the running state
[2024-02-12T12:02:18.475+0000] {local_task_job.py:147} INFO - Task is not able to be run
[2024-02-12T12:02:18.455+0000] {standard_task_runner.py:82} INFO - Running: ['***', 'tasks', 'run', 'bigdata', 'big_data', 'manual__2024-02-12T12:02:01.558922+00:00', '--job-id', '1060', '--raw', '--subdir', 'DAGS_FOLDER/bigdata.py', '--cfg-path', '/tmp/tmpomlnx5ei']
[2024-02-12T12:02:18.485+0000] {standard_task_runner.py:83} INFO - Job 1060: Subtask big_data
[2024-02-12T12:02:18.874+0000] {task_command.py:388} INFO - Running <TaskInstance: bigdata.big_data manual__2024-02-12T12:02:01.558922+00:00 [running]> on host 253264584ea3
[2024-02-12T12:02:19.333+0000] {taskinstance.py:1509} INFO - Exporting the following env vars:
AIRFLOW_CTX_DAG_OWNER=***
AIRFLOW_CTX_DAG_ID=bigdata
AIRFLOW_CTX_TASK_ID=big_data
AIRFLOW_CTX_EXECUTION_DATE=2024-02-12T12:02:01.558922+00:00
AIRFLOW_CTX_TRY_NUMBER=1
AIRFLOW_CTX_DAG_RUN_ID=manual__2024-02-12T12:02:01.558922+00:00
[2024-02-12T12:02:19.338+0000] {taskinstance.py:1768} ERROR - Task failed with exception
Traceback (most recent call last):
  File "/home/airflow/.local/lib/python3.7/site-packages/airflow/models/baseoperator.py", line 1113, in execute
    raise NotImplementedError()
NotImplementedError
[2024-02-12T12:02:19.391+0000] {taskinstance.py:1323} INFO - Marking task as FAILED. dag_id=bigdata, task_id=big_data, execution_date=20240212T120201, start_date=20240212T120218, end_date=20240212T120219
[2024-02-12T12:02:19.523+0000] {standard_task_runner.py:105} ERROR - Failed to execute job 1060 for task big_data (; 1960)
[2024-02-12T12:02:19.610+0000] {local_task_job.py:208} INFO - Task exited with return code 1
[2024-02-12T12:02:19.797+0000] {taskinstance.py:2578} INFO - 0 downstream tasks scheduled from follow-on schedule check
