[2024-02-10T22:00:19.533+0000] {processor.py:153} INFO - Started process (PID=176314) to work on /opt/airflow/dags/bancodedados2.py
[2024-02-10T22:00:19.535+0000] {processor.py:743} INFO - Processing file /opt/airflow/dags/bancodedados2.py for tasks to queue
[2024-02-10T22:00:19.536+0000] {logging_mixin.py:137} INFO - [2024-02-10T22:00:19.536+0000] {dagbag.py:538} INFO - Filling up the DagBag from /opt/airflow/dags/bancodedados2.py
[2024-02-10T22:00:19.855+0000] {logging_mixin.py:137} INFO - [2024-02-10T22:00:19.840+0000] {dagbag.py:343} ERROR - Failed to import: /opt/airflow/dags/bancodedados2.py
Traceback (most recent call last):
  File "/home/airflow/.local/lib/python3.7/site-packages/airflow/models/dagbag.py", line 339, in parse
    loader.exec_module(new_module)
  File "<frozen importlib._bootstrap_external>", line 728, in exec_module
  File "<frozen importlib._bootstrap>", line 219, in _call_with_frames_removed
  File "/opt/airflow/dags/bancodedados2.py", line 25, in <module>
    dag=dag
  File "/home/airflow/.local/lib/python3.7/site-packages/airflow/models/baseoperator.py", line 394, in apply_defaults
    result = func(self, **kwargs, default_args=default_args)
  File "/home/airflow/.local/lib/python3.7/site-packages/airflow/providers/postgres/operators/postgres.py", line 84, in __init__
    super().__init__(conn_id=postgres_conn_id, **kwargs)
  File "/home/airflow/.local/lib/python3.7/site-packages/airflow/models/baseoperator.py", line 394, in apply_defaults
    result = func(self, **kwargs, default_args=default_args)
  File "/home/airflow/.local/lib/python3.7/site-packages/airflow/providers/common/sql/operators/sql.py", line 226, in __init__
    super().__init__(**kwargs)
  File "/home/airflow/.local/lib/python3.7/site-packages/airflow/models/baseoperator.py", line 394, in apply_defaults
    result = func(self, **kwargs, default_args=default_args)
  File "/home/airflow/.local/lib/python3.7/site-packages/airflow/providers/common/sql/operators/sql.py", line 131, in __init__
    super().__init__(**kwargs)
  File "/home/airflow/.local/lib/python3.7/site-packages/airflow/models/baseoperator.py", line 394, in apply_defaults
    result = func(self, **kwargs, default_args=default_args)
  File "/home/airflow/.local/lib/python3.7/site-packages/airflow/models/baseoperator.py", line 743, in __init__
    f"Invalid arguments were passed to {self.__class__.__name__} (task_id: {task_id}). "
airflow.exceptions.AirflowException: Invalid arguments were passed to PostgresOperator (task_id: create_table). Invalid arguments were:
**kwargs: {'postgress_conn_id': 'postgres'}
[2024-02-10T22:00:19.856+0000] {processor.py:755} WARNING - No viable dags retrieved from /opt/airflow/dags/bancodedados2.py
[2024-02-10T22:00:19.937+0000] {processor.py:175} INFO - Processing /opt/airflow/dags/bancodedados2.py took 0.427 seconds
[2024-02-10T22:00:27.136+0000] {processor.py:153} INFO - Started process (PID=176339) to work on /opt/airflow/dags/bancodedados2.py
[2024-02-10T22:00:27.142+0000] {processor.py:743} INFO - Processing file /opt/airflow/dags/bancodedados2.py for tasks to queue
[2024-02-10T22:00:27.144+0000] {logging_mixin.py:137} INFO - [2024-02-10T22:00:27.143+0000] {dagbag.py:538} INFO - Filling up the DagBag from /opt/airflow/dags/bancodedados2.py
[2024-02-10T22:00:27.228+0000] {logging_mixin.py:137} INFO - [2024-02-10T22:00:27.225+0000] {dagbag.py:343} ERROR - Failed to import: /opt/airflow/dags/bancodedados2.py
Traceback (most recent call last):
  File "/home/airflow/.local/lib/python3.7/site-packages/airflow/models/dagbag.py", line 339, in parse
    loader.exec_module(new_module)
  File "<frozen importlib._bootstrap_external>", line 728, in exec_module
  File "<frozen importlib._bootstrap>", line 219, in _call_with_frames_removed
  File "/opt/airflow/dags/bancodedados2.py", line 25, in <module>
    dag=dag
  File "/home/airflow/.local/lib/python3.7/site-packages/airflow/models/baseoperator.py", line 394, in apply_defaults
    result = func(self, **kwargs, default_args=default_args)
  File "/home/airflow/.local/lib/python3.7/site-packages/airflow/providers/postgres/operators/postgres.py", line 84, in __init__
    super().__init__(conn_id=postgres_conn_id, **kwargs)
  File "/home/airflow/.local/lib/python3.7/site-packages/airflow/models/baseoperator.py", line 394, in apply_defaults
    result = func(self, **kwargs, default_args=default_args)
  File "/home/airflow/.local/lib/python3.7/site-packages/airflow/providers/common/sql/operators/sql.py", line 226, in __init__
    super().__init__(**kwargs)
  File "/home/airflow/.local/lib/python3.7/site-packages/airflow/models/baseoperator.py", line 394, in apply_defaults
    result = func(self, **kwargs, default_args=default_args)
  File "/home/airflow/.local/lib/python3.7/site-packages/airflow/providers/common/sql/operators/sql.py", line 131, in __init__
    super().__init__(**kwargs)
  File "/home/airflow/.local/lib/python3.7/site-packages/airflow/models/baseoperator.py", line 394, in apply_defaults
    result = func(self, **kwargs, default_args=default_args)
  File "/home/airflow/.local/lib/python3.7/site-packages/airflow/models/baseoperator.py", line 743, in __init__
    f"Invalid arguments were passed to {self.__class__.__name__} (task_id: {task_id}). "
airflow.exceptions.AirflowException: Invalid arguments were passed to PostgresOperator (task_id: create_table). Invalid arguments were:
**kwargs: {'postgress_conn_id': 'postgres'}
[2024-02-10T22:00:27.229+0000] {processor.py:755} WARNING - No viable dags retrieved from /opt/airflow/dags/bancodedados2.py
[2024-02-10T22:00:27.317+0000] {processor.py:175} INFO - Processing /opt/airflow/dags/bancodedados2.py took 0.188 seconds
[2024-02-10T22:00:33.085+0000] {processor.py:153} INFO - Started process (PID=176363) to work on /opt/airflow/dags/bancodedados2.py
[2024-02-10T22:00:33.087+0000] {processor.py:743} INFO - Processing file /opt/airflow/dags/bancodedados2.py for tasks to queue
[2024-02-10T22:00:33.088+0000] {logging_mixin.py:137} INFO - [2024-02-10T22:00:33.088+0000] {dagbag.py:538} INFO - Filling up the DagBag from /opt/airflow/dags/bancodedados2.py
[2024-02-10T22:00:33.152+0000] {logging_mixin.py:137} INFO - [2024-02-10T22:00:33.150+0000] {dagbag.py:343} ERROR - Failed to import: /opt/airflow/dags/bancodedados2.py
Traceback (most recent call last):
  File "/home/airflow/.local/lib/python3.7/site-packages/airflow/models/dagbag.py", line 339, in parse
    loader.exec_module(new_module)
  File "<frozen importlib._bootstrap_external>", line 728, in exec_module
  File "<frozen importlib._bootstrap>", line 219, in _call_with_frames_removed
  File "/opt/airflow/dags/bancodedados2.py", line 25, in <module>
    dag=dag
  File "/home/airflow/.local/lib/python3.7/site-packages/airflow/models/baseoperator.py", line 394, in apply_defaults
    result = func(self, **kwargs, default_args=default_args)
  File "/home/airflow/.local/lib/python3.7/site-packages/airflow/providers/postgres/operators/postgres.py", line 84, in __init__
    super().__init__(conn_id=postgres_conn_id, **kwargs)
  File "/home/airflow/.local/lib/python3.7/site-packages/airflow/models/baseoperator.py", line 394, in apply_defaults
    result = func(self, **kwargs, default_args=default_args)
  File "/home/airflow/.local/lib/python3.7/site-packages/airflow/providers/common/sql/operators/sql.py", line 226, in __init__
    super().__init__(**kwargs)
  File "/home/airflow/.local/lib/python3.7/site-packages/airflow/models/baseoperator.py", line 394, in apply_defaults
    result = func(self, **kwargs, default_args=default_args)
  File "/home/airflow/.local/lib/python3.7/site-packages/airflow/providers/common/sql/operators/sql.py", line 131, in __init__
    super().__init__(**kwargs)
  File "/home/airflow/.local/lib/python3.7/site-packages/airflow/models/baseoperator.py", line 394, in apply_defaults
    result = func(self, **kwargs, default_args=default_args)
  File "/home/airflow/.local/lib/python3.7/site-packages/airflow/models/baseoperator.py", line 743, in __init__
    f"Invalid arguments were passed to {self.__class__.__name__} (task_id: {task_id}). "
airflow.exceptions.AirflowException: Invalid arguments were passed to PostgresOperator (task_id: create_table). Invalid arguments were:
**kwargs: {'postgress_conn_id': 'postgres'}
[2024-02-10T22:00:33.152+0000] {processor.py:755} WARNING - No viable dags retrieved from /opt/airflow/dags/bancodedados2.py
[2024-02-10T22:00:33.180+0000] {processor.py:175} INFO - Processing /opt/airflow/dags/bancodedados2.py took 0.103 seconds
[2024-02-10T22:00:38.345+0000] {processor.py:153} INFO - Started process (PID=176401) to work on /opt/airflow/dags/bancodedados2.py
[2024-02-10T22:00:38.372+0000] {processor.py:743} INFO - Processing file /opt/airflow/dags/bancodedados2.py for tasks to queue
[2024-02-10T22:00:38.373+0000] {logging_mixin.py:137} INFO - [2024-02-10T22:00:38.372+0000] {dagbag.py:538} INFO - Filling up the DagBag from /opt/airflow/dags/bancodedados2.py
[2024-02-10T22:00:38.479+0000] {logging_mixin.py:137} INFO - [2024-02-10T22:00:38.467+0000] {dagbag.py:343} ERROR - Failed to import: /opt/airflow/dags/bancodedados2.py
Traceback (most recent call last):
  File "/home/airflow/.local/lib/python3.7/site-packages/airflow/models/dagbag.py", line 339, in parse
    loader.exec_module(new_module)
  File "<frozen importlib._bootstrap_external>", line 728, in exec_module
  File "<frozen importlib._bootstrap>", line 219, in _call_with_frames_removed
  File "/opt/airflow/dags/bancodedados2.py", line 25, in <module>
    dag=dag
  File "/home/airflow/.local/lib/python3.7/site-packages/airflow/models/baseoperator.py", line 394, in apply_defaults
    result = func(self, **kwargs, default_args=default_args)
  File "/home/airflow/.local/lib/python3.7/site-packages/airflow/providers/postgres/operators/postgres.py", line 84, in __init__
    super().__init__(conn_id=postgres_conn_id, **kwargs)
  File "/home/airflow/.local/lib/python3.7/site-packages/airflow/models/baseoperator.py", line 394, in apply_defaults
    result = func(self, **kwargs, default_args=default_args)
  File "/home/airflow/.local/lib/python3.7/site-packages/airflow/providers/common/sql/operators/sql.py", line 226, in __init__
    super().__init__(**kwargs)
  File "/home/airflow/.local/lib/python3.7/site-packages/airflow/models/baseoperator.py", line 394, in apply_defaults
    result = func(self, **kwargs, default_args=default_args)
  File "/home/airflow/.local/lib/python3.7/site-packages/airflow/providers/common/sql/operators/sql.py", line 131, in __init__
    super().__init__(**kwargs)
  File "/home/airflow/.local/lib/python3.7/site-packages/airflow/models/baseoperator.py", line 394, in apply_defaults
    result = func(self, **kwargs, default_args=default_args)
  File "/home/airflow/.local/lib/python3.7/site-packages/airflow/models/baseoperator.py", line 743, in __init__
    f"Invalid arguments were passed to {self.__class__.__name__} (task_id: {task_id}). "
airflow.exceptions.AirflowException: Invalid arguments were passed to PostgresOperator (task_id: create_table). Invalid arguments were:
**kwargs: {'postgress_conn_id': 'postgres'}
[2024-02-10T22:00:38.479+0000] {processor.py:755} WARNING - No viable dags retrieved from /opt/airflow/dags/bancodedados2.py
[2024-02-10T22:00:38.533+0000] {processor.py:175} INFO - Processing /opt/airflow/dags/bancodedados2.py took 0.202 seconds
[2024-02-10T22:00:44.367+0000] {processor.py:153} INFO - Started process (PID=176427) to work on /opt/airflow/dags/bancodedados2.py
[2024-02-10T22:00:44.368+0000] {processor.py:743} INFO - Processing file /opt/airflow/dags/bancodedados2.py for tasks to queue
[2024-02-10T22:00:44.370+0000] {logging_mixin.py:137} INFO - [2024-02-10T22:00:44.370+0000] {dagbag.py:538} INFO - Filling up the DagBag from /opt/airflow/dags/bancodedados2.py
[2024-02-10T22:00:44.426+0000] {logging_mixin.py:137} INFO - [2024-02-10T22:00:44.424+0000] {dagbag.py:343} ERROR - Failed to import: /opt/airflow/dags/bancodedados2.py
Traceback (most recent call last):
  File "/home/airflow/.local/lib/python3.7/site-packages/airflow/models/dagbag.py", line 339, in parse
    loader.exec_module(new_module)
  File "<frozen importlib._bootstrap_external>", line 728, in exec_module
  File "<frozen importlib._bootstrap>", line 219, in _call_with_frames_removed
  File "/opt/airflow/dags/bancodedados2.py", line 25, in <module>
    dag=dag
  File "/home/airflow/.local/lib/python3.7/site-packages/airflow/models/baseoperator.py", line 394, in apply_defaults
    result = func(self, **kwargs, default_args=default_args)
  File "/home/airflow/.local/lib/python3.7/site-packages/airflow/providers/postgres/operators/postgres.py", line 84, in __init__
    super().__init__(conn_id=postgres_conn_id, **kwargs)
  File "/home/airflow/.local/lib/python3.7/site-packages/airflow/models/baseoperator.py", line 394, in apply_defaults
    result = func(self, **kwargs, default_args=default_args)
  File "/home/airflow/.local/lib/python3.7/site-packages/airflow/providers/common/sql/operators/sql.py", line 226, in __init__
    super().__init__(**kwargs)
  File "/home/airflow/.local/lib/python3.7/site-packages/airflow/models/baseoperator.py", line 394, in apply_defaults
    result = func(self, **kwargs, default_args=default_args)
  File "/home/airflow/.local/lib/python3.7/site-packages/airflow/providers/common/sql/operators/sql.py", line 131, in __init__
    super().__init__(**kwargs)
  File "/home/airflow/.local/lib/python3.7/site-packages/airflow/models/baseoperator.py", line 394, in apply_defaults
    result = func(self, **kwargs, default_args=default_args)
  File "/home/airflow/.local/lib/python3.7/site-packages/airflow/models/baseoperator.py", line 743, in __init__
    f"Invalid arguments were passed to {self.__class__.__name__} (task_id: {task_id}). "
airflow.exceptions.AirflowException: Invalid arguments were passed to PostgresOperator (task_id: create_table). Invalid arguments were:
**kwargs: {'postgress_conn_id': 'postgres'}
[2024-02-10T22:00:44.426+0000] {processor.py:755} WARNING - No viable dags retrieved from /opt/airflow/dags/bancodedados2.py
[2024-02-10T22:00:44.452+0000] {processor.py:175} INFO - Processing /opt/airflow/dags/bancodedados2.py took 0.094 seconds
