[2024-02-10T22:02:03.935+0000] {taskinstance.py:1083} INFO - Dependencies all met for <TaskInstance: bancodedados.create_table manual__2024-02-10T22:02:02.544108+00:00 [queued]>
[2024-02-10T22:02:03.961+0000] {taskinstance.py:1083} INFO - Dependencies all met for <TaskInstance: bancodedados.create_table manual__2024-02-10T22:02:02.544108+00:00 [queued]>
[2024-02-10T22:02:03.961+0000] {taskinstance.py:1279} INFO - 
--------------------------------------------------------------------------------
[2024-02-10T22:02:03.961+0000] {taskinstance.py:1280} INFO - Starting attempt 1 of 1
[2024-02-10T22:02:03.961+0000] {taskinstance.py:1281} INFO - 
--------------------------------------------------------------------------------
[2024-02-10T22:02:03.985+0000] {taskinstance.py:1300} INFO - Executing <Task(PostgresOperator): create_table> on 2024-02-10 22:02:02.544108+00:00
[2024-02-10T22:02:03.993+0000] {standard_task_runner.py:55} INFO - Started process 34481 to run task
[2024-02-10T22:02:03.998+0000] {standard_task_runner.py:82} INFO - Running: ['***', 'tasks', 'run', 'bancodedados', 'create_table', 'manual__2024-02-10T22:02:02.544108+00:00', '--job-id', '918', '--raw', '--subdir', 'DAGS_FOLDER/bancodedados.py', '--cfg-path', '/tmp/tmp4you80v7']
[2024-02-10T22:02:03.999+0000] {standard_task_runner.py:83} INFO - Job 918: Subtask create_table
[2024-02-10T22:02:04.113+0000] {task_command.py:388} INFO - Running <TaskInstance: bancodedados.create_table manual__2024-02-10T22:02:02.544108+00:00 [running]> on host f8c98ce69515
[2024-02-10T22:02:04.336+0000] {taskinstance.py:1509} INFO - Exporting the following env vars:
AIRFLOW_CTX_DAG_OWNER=***
AIRFLOW_CTX_DAG_ID=bancodedados
AIRFLOW_CTX_TASK_ID=create_table
AIRFLOW_CTX_EXECUTION_DATE=2024-02-10T22:02:02.544108+00:00
AIRFLOW_CTX_TRY_NUMBER=1
AIRFLOW_CTX_DAG_RUN_ID=manual__2024-02-10T22:02:02.544108+00:00
[2024-02-10T22:02:04.337+0000] {sql.py:254} INFO - Executing: create table if not exists teste(id int);
[2024-02-10T22:02:04.457+0000] {taskinstance.py:1768} ERROR - Task failed with exception
Traceback (most recent call last):
  File "/home/airflow/.local/lib/python3.7/site-packages/airflow/providers/common/sql/operators/sql.py", line 255, in execute
    hook = self.get_db_hook()
  File "/home/airflow/.local/lib/python3.7/site-packages/airflow/providers/common/sql/operators/sql.py", line 179, in get_db_hook
    return self._hook
  File "/home/airflow/.local/lib/python3.7/site-packages/cached_property.py", line 36, in __get__
    value = obj.__dict__[self.func.__name__] = self.func(obj)
  File "/home/airflow/.local/lib/python3.7/site-packages/airflow/providers/common/sql/operators/sql.py", line 141, in _hook
    conn = BaseHook.get_connection(self.conn_id)
  File "/home/airflow/.local/lib/python3.7/site-packages/airflow/hooks/base.py", line 72, in get_connection
    conn = Connection.get_connection_from_secrets(conn_id)
  File "/home/airflow/.local/lib/python3.7/site-packages/airflow/models/connection.py", line 435, in get_connection_from_secrets
    raise AirflowNotFoundException(f"The conn_id `{conn_id}` isn't defined")
airflow.exceptions.AirflowNotFoundException: The conn_id `postgres` isn't defined
[2024-02-10T22:02:04.492+0000] {taskinstance.py:1323} INFO - Marking task as FAILED. dag_id=bancodedados, task_id=create_table, execution_date=20240210T220202, start_date=20240210T220203, end_date=20240210T220204
[2024-02-10T22:02:04.522+0000] {standard_task_runner.py:105} ERROR - Failed to execute job 918 for task create_table (The conn_id `postgres` isn't defined; 34481)
[2024-02-10T22:02:04.545+0000] {local_task_job.py:208} INFO - Task exited with return code 1
[2024-02-10T22:02:04.600+0000] {taskinstance.py:2578} INFO - 0 downstream tasks scheduled from follow-on schedule check
